<?xml version="1.0" ?>
<!-- =================================================================================== -->
<!-- |    This document was autogenerated by xacro from robot.urdf.xacro               | -->
<!-- |    EDITING THIS FILE BY HAND IS NOT RECOMMENDED                                 | -->
<!-- =================================================================================== -->
<robot name="a4">
  <link name="arm_link_0">
    <taichi>
      <bodytype type='rigid'/>
    </taichi>
    <visual>
      <origin xyz="0 0 0.25"/>
      <geometry>
        <box size="0.5 0.5 0.5"/>
      </geometry>
      <material name="green">
        <color rgba="0 1.0 0 0.5"/>
      </material>
    </visual>
  </link>
  <link name="arm_link_1">
    <taichi>
      <bodytype type='soft'/>
    </taichi>
    <visual>
      <origin xyz="0 0 0.25"/>
      <geometry>
        <cylinder length="0.5" radius="0.1"/>
      </geometry>
      <material name="blue">
        <color rgba="0 0.0 1 0.5"/>
      </material>
    </visual>
  </link>
  <link name="arm_link_2">
    <!-- <taichi> -->
    <!--   <bodytype type='Soft'/> -->
    <!-- </taichi> -->
    <visual>
      <origin rpy="0 0 0" xyz="0 0 0.25"/>
      <geometry>
        <cylinder length="0.5" radius="0.1"/>
      </geometry>
      <material name="cyan">
        <color rgba="0 1.0 1 0.5"/>
      </material>
    </visual>
  </link>
  <link name="arm_flange"/>
  <joint name="arm_joint_1" type="revolute">
    <parent link="arm_link_0"/>
    <child link="arm_link_1"/>
    <origin rpy="0 0 0" xyz="0 0 0.5"/>
    <axis xyz="0 0 1"/>
    <limit effort="10" lower="-1" upper="1" velocity="1"/>
  </joint>
  <joint name="arm_joint_2" type="revolute">
    <parent link="arm_link_1"/>
    <child link="arm_link_2"/>
    <origin rpy="1.57 0 0" xyz="0 0 0.5"/>
    <axis xyz="1 0 0"/>
    <limit effort="10" lower="-1" upper="1" velocity="1"/>
  </joint>
  <joint name="arm_flange" type="fixed">
    <parent link="arm_link_2"/>
    <child link="arm_flange"/>
    <origin rpy="0 0 0" xyz="0 0 0.5"/>
  </joint>
  <link name="world"/>
  <joint name="robot_base" type="fixed">
    <parent link="world"/>
    <child link="arm_link_0"/>
  </joint>
</robot>
