<robot xmlns:xacro="http://www.ros.org/wiki/xacro" name="a4">

  <xacro:macro name="a4_robot" params="prefix">
    <link name="${prefix}_link_0">
      <visual>
        <origin xyz="0 0 0.25"/>
        <geometry>
          <box size="0.5 0.5 0.5"/>
        </geometry>
        <material name="green">
          <color rgba="0 1.0 0 0.5"/>
        </material>
      </visual>
    </link>

    <link name="${prefix}_link_1">
      <visual>
        <origin xyz="0 0 0.25"/>
        <geometry>
          <cylinder length="0.5" radius="0.1"/>
        </geometry>
        <material name="blue">
          <color rgba="0 0.0 1 0.5"/>
        </material>
      </visual>
    </link>

    <link name="${prefix}_link_2">
      <visual>
        <origin xyz="0 0 0.25" rpy="0 0 0"/>
        <geometry>
          <cylinder length="0.5" radius="0.1"/>
        </geometry>
        <material name="cyan">
          <color rgba="0 1.0 1 0.5"/>
        </material>
      </visual>
    </link>

    <link name="${prefix}_flange"/>

    <joint name="${prefix}_joint_1" type="revolute">
      <parent link="${prefix}_link_0"/>
      <child link="${prefix}_link_1"/>
      <origin xyz="0 0 0.5" rpy="0 0 0"/>
      <axis xyz="0 0 1"/>
      <limit lower="-1" upper="1" effort="10" velocity="1"/>
    </joint>

    <joint name="${prefix}_joint_2" type="revolute">
      <parent link="${prefix}_link_1"/>
      <child link="${prefix}_link_2"/>
      <origin xyz="0 0 0.5" rpy="1.57 0 0"/>
      <axis xyz="1 0 0"/>
      <limit lower="-1" upper="1" effort="10" velocity="1"/>
    </joint>

    <joint name="${prefix}_flange" type="fixed">
      <parent link="${prefix}_link_2"/>
      <child link="${prefix}_flange"/>
      <origin xyz="0 0 0.5" rpy="0 0 0"/>
    </joint>

  </xacro:macro>

</robot>
